Workbook

Sheet Tableau de Bord
A1: PERMATEL — SUIVI DES TÂCHES
A2: Plan d'action · Audit du 2026-05-10 · Dernière mise à jour : 2026-08-14 (Phase 6 ERP livrée — fondations transverses)
A4: Total Tâches | B4: À faire | C4: En cours | D4: Complétées | E4: Bloquées | G4: Avancement Global
A5: =COUNTA(Tâches!A4:A200)-1 | B5: =COUNTIF(Tâches!G4:G200,"À faire") | C5: =COUNTIF(Tâches!G4:G200,"En cours") | D5: =COUNTIF(Tâches!G4:G200,"Complété") | E5: =COUNTIF(Tâches!G4:G200,"Bloqué") | G5: =IFERROR(D5/A5,0)
A7: AVANCEMENT PAR PHASE
A8: Phase | B8: Description | C8: Durée | D8: Nb tâches | E8: Complétées | F8: % Phase
A9: Phase 1 | B9: PHASE 1 — Sécurité | C9: ~2j | D9: 5 | E9: =COUNTIFS(Tâches!B4:B200,"Phase 1",Tâches!G4:G200,"Complété") | F9: =IFERROR(E9/D9,0)
A10: Phase 2 | B10: PHASE 2 — Backend complet | C10: ~5j | D10: 5 | E10: =COUNTIFS(Tâches!B4:B200,"Phase 2",Tâches!G4:G200,"Complété") | F10: =IFERROR(E10/D10,0)
A11: Phase 3 | B11: PHASE 3 — Tests | C11: ~4j | D11: 4 | E11: =COUNTIFS(Tâches!B4:B200,"Phase 3",Tâches!G4:G200,"Complété") | F11: =IFERROR(E11/D11,0)
A12: Phase 4 | B12: PHASE 4 — Frontend métier | C12: ~10j | D12: 7 | E12: =COUNTIFS(Tâches!B4:B200,"Phase 4",Tâches!G4:G200,"Complété") | F12: =IFERROR(E12/D12,0)
A13: Phase 5 | B13: PHASE 5 — Qualité & Production | C13: ~2j | D13: 5 | E13: =COUNTIFS(Tâches!B4:B200,"Phase 5",Tâches!G4:G200,"Complété") | F13: =IFERROR(E13/D13,0)
A14: Phase 6 | B14: PHASE 6 — Odoo : Fondations | C14: ~4j | D14: 10 | E14: =COUNTIFS(Tâches!B4:B200,"Phase 6",Tâches!G4:G200,"Complété") | F14: =IFERROR(E14/D14,0)
A15: Phase 7 | B15: PHASE 7 — Odoo : Infra + Partenaires (F1) | C15: ~5j | D15: 5 | E15: =COUNTIFS(Tâches!B4:B200,"Phase 7",Tâches!G4:G200,"Complété") | F15: =IFERROR(E15/D15,0)
A16: Phase 8 | B16: PHASE 8 — Odoo : Commande → Devis/Facture (F2/F4) | C16: ~3.5j | D16: 4 | E16: =COUNTIFS(Tâches!B4:B200,"Phase 8",Tâches!G4:G200,"Complété") | F16: =IFERROR(E16/D16,0)
A17: Phase 9 | B17: PHASE 9 — Odoo : Vacation → Feuille de temps (F3) | C17: ~1j | D17: 1 | E17: =COUNTIFS(Tâches!B4:B200,"Phase 9",Tâches!G4:G200,"Complété") | F17: =IFERROR(E17/D17,0)
A18: Phase 10 | B18: PHASE 10 — Odoo : Planning agents (F5) | C18: ~4.5j | D18: 3 | E18: =COUNTIFS(Tâches!B4:B200,"Phase 10",Tâches!G4:G200,"Complété") | F18: =IFERROR(E18/D18,0)
A20: Phase 11 | B20: PHASE 11 — Téléphonie : Fondations backend | C20: ~6.5j | D20: 7 | E20: =COUNTIFS(Tâches!B4:B200,"Phase 11",Tâches!G4:G200,"Complété") | F20: =IFERROR(E20/D20,0)
A21: Phase 11bis | B21: PHASE 11bis — Téléphonie : Infra WebSocket (Flask-SocketIO) | C21: ~3j | D21: 4 | E21: =COUNTIFS(Tâches!B4:B200,"Phase 11bis",Tâches!G4:G200,"Complété") | F21: =IFERROR(E21/D21,0)
A22: Phase 12 | B22: PHASE 12 — Téléphonie : Connecteur FusionPBX (ESL) | C22: ~7j | D22: 15 | E22: =COUNTIFS(Tâches!B4:B200,"Phase 12",Tâches!G4:G200,"Complété") | F22: =IFERROR(E22/D22,0)
A23: Phase 13 | B23: PHASE 13 — Téléphonie : Supervision frontend (WebSocket) | C23: ~5j | D23: 3 | E23: =COUNTIFS(Tâches!B4:B200,"Phase 13",Tâches!G4:G200,"Complété") | F23: =IFERROR(E23/D23,0)
A24: Phase 14 | B24: PHASE 14 — Téléphonie : Webhook CDR + Rapports | C24: ~2.5j | D24: 4 | E24: =COUNTIFS(Tâches!B4:B200,"Phase 14",Tâches!G4:G200,"Complété") | F24: =IFERROR(E24/D24,0)
A25: Phase 15 | B25: PHASE 15 — Téléphonie : Connecteur Asterisk (AMI) | C25: ~2.5j | D25: 2 | E25: =COUNTIFS(Tâches!B4:B200,"Phase 15",Tâches!G4:G200,"Complété") | F25: =IFERROR(E25/D25,0)
A26: Phase 16 | B26: PHASE 16 — Rapports enrichis (prises de service, géoIP, filtre CDR) | C26: ~2j | D26: 4 | E26: =COUNTIFS(Tâches!B4:B200,"Phase 16",Tâches!G4:G200,"Complété") | F26: =IFERROR(E26/D26,0)
A27: Phase 17 | B27: PHASE 17 — Profil utilisateur (self-service) | C27: ~0.5j | D27: 1 | E27: =COUNTIFS(Tâches!B4:B200,"Phase 17",Tâches!G4:G200,"Complété") | F27: =IFERROR(E27/D27,0)
A28: LÉGENDE — STATUTS
A29: À faire | B29: En cours | C29: Complété | D29: Bloqué | E29: Abandonné

Sheet Tâches
A1: REGISTRE DES TÂCHES — PERMATEL
A2: Mettre à jour le statut et la date de complétion après chaque tâche terminée.
A4: ID | B4: Phase | C4: Domaine | D4: Priorité | E4: Titre | F4: Description | G4: Statut | H4: Effort | I4: Fichiers impactés | J4: Dépendances | K4: Date début | L4: Date fin | M4: Notes
A5: 1.1 | B5: Phase 1 | C5: Sécurité | D5: 🔴 Critique | E5: Réactiver @jwt_required() + @tenant_required() sur clients, sites, contacts | F5: Décommenter les 20 @jwt_required(), remplacer par @tenant_required(). Filtrer chaque endpoint par g.tenant.id. | G5: Complété | H5: ½j | I5: routes/clients.py · sites.py · contacts.py | K5: 2026-05-10 | L5: 2026-05-10
A6: 1.2 | B6: Phase 1 | C6: Sécurité | D6: 🔴 Critique | E6: Appliquer @role_required() aux endpoints d'administration | F6: Tenants création/suppression = ADMIN. Users création/update role = ADMIN. Demandes clôture = MANAGER|ADMIN. | G6: Complété | H6: ½j | I6: routes/tenants.py · users.py · demandes.py | K6: 2026-05-10 | L6: 2026-05-10
A7: 1.3 | B7: Phase 1 | C7: Infra | D7: 🔴 Critique | E7: Corriger docker-compose.yml pour utiliser des variables d'environnement | F7: Remplacer credentials et JWT_SECRET_KEY hardcodés par ${VAR}. Créer .env.example documenté. | G7: Complété | H7: 2h | I7: docker-compose.yml · .env.example (nouveau) | K7: 2026-05-10 | L7: 2026-05-10
A8: 1.4 | B8: Phase 1 | C8: Frontend | D8: 🔴 Critique | E8: Brancher la guard de navigation Vue Router sur le store Pinia | F8: Remplacer isAuthenticated=false par authStore.isAuthenticated. Gérer redirect returnUrl. | G8: Complété | H8: 2h | I8: frontend/src/router/index.js | K8: 2026-05-10 | L8: 2026-05-10
A9: 1.5 | B9: Phase 1 | C9: Frontend | D9: 🔴 Critique | E9: Ajouter l'intercepteur de refresh automatique des tokens | F9: Sur 401: appeler /api/auth/refresh, mettre à jour store, rejouer requête. Si refresh échoue: logout + redirect /login. | G9: Complété | H9: ½j | I9: services/http/interceptor.js · store/auth.js | J9: 1.4 | K9: 2026-05-10 | L9: 2026-05-10
A10: 2.1 | B10: Phase 2 | C10: Backend | D10: 🟡 Haute | E10: Réactiver et compléter le blueprint Prestataires | F10: Décommenter dans __init__.py. Écrire CRUD complet avec @tenant_required(). Prérequis pour 2.2. | G10: Complété | H10: 1j | I10: routes/prestataires.py · app/__init__.py | M10: [Audit 14/08] déjà implémenté (routes réellement enregistrées dans app/__init__.py / flow select-tenant en place côté frontend) — dates de complétion non tracées à l'époque.
A11: 2.2 | B11: Phase 2 | C11: Backend | D11: 🟡 Haute | E11: Créer les routes Agents de sécurité | F11: Blueprint /api/agents-securite. CRUD + filtrage tenant. Recherche par matricule. Dépend de 2.1. | G11: Complété | H11: 1j | I11: routes/agents_securite.py (nouveau) · app/__init__.py | J11: 2.1 | M11: [Audit 14/08] déjà implémenté (routes réellement enregistrées dans app/__init__.py / flow select-tenant en place côté frontend) — dates de complétion non tracées à l'époque.
A12: 2.3 | B12: Phase 2 | C12: Backend | D12: 🟡 Haute | E12: Créer les routes Interactions (sous-ressource de Demandes) | F12: GET /api/demandes/{id}/interactions, POST création. Si type=CHANGEMENT_STATUT, mettre à jour statut demande. | G12: Complété | H12: 1j | I12: routes/demandes.py ou interactions.py (nouveau) | M12: [Audit 14/08] déjà implémenté (routes réellement enregistrées dans app/__init__.py / flow select-tenant en place côté frontend) — dates de complétion non tracées à l'époque.
A13: 2.4 | B13: Phase 2 | C13: Backend | D13: 🟡 Haute | E13: Créer les routes Fichiers (upload/download) | F13: POST upload multipart, GET liste, GET download. Chemin isolé par tenant. Validation type MIME + taille max. | G13: Complété | H13: 1j | I13: routes/fichiers.py (nouveau) · app/__init__.py | M13: [Audit 14/08] déjà implémenté (routes réellement enregistrées dans app/__init__.py / flow select-tenant en place côté frontend) — dates de complétion non tracées à l'époque.
A14: 2.5 | B14: Phase 2 | C14: Frontend | D14: 🟡 Haute | E14: Implémenter le flow select-tenant côté frontend | F14: Après login si tenants.length > 1: afficher modale. Appeler /api/auth/select-tenant. Stocker tid dans store. | G14: Complété | H14: ½j | I14: store/auth.js · views/TenantSelectView.vue (nouveau) | J14: 1.4 | M14: [Audit 14/08] déjà implémenté (routes réellement enregistrées dans app/__init__.py / flow select-tenant en place côté frontend) — dates de complétion non tracées à l'époque.
A15: 3.1 | B15: Phase 3 | C15: Tests | D15: 🟢 Normale | E15: Tests Auth — login, logout, refresh | F15: Login OK/KO/inactif/sans tenant. Logout révocation. Double logout. Refresh OK/inactivité/révoqué. | G15: Complété | H15: 1j | I15: tests/test_auth_login.py · test_auth_logout.py · test_auth_refresh.py | M15: [Audit 14/08] fichiers de tests existent et sont complets (test_auth_login.py, test_auth_logout.py, test_auth_refresh.py, test_clients.py, test_users.py, test_demandes.py, etc. — 394 tests backend au total).
A16: 3.2 | B16: Phase 3 | C16: Tests | D16: 🟢 Normale | E16: Tests Clients, Sites, Contacts | F16: Pour chaque: list, get, create, update, deactivate. Tester isolation tenant A vs B. | G16: Complété | H16: 1j | I16: tests/test_clients.py · test_sites.py · test_contacts.py | J16: 1.1 | M16: [Audit 14/08] fichiers de tests existent et sont complets (test_auth_login.py, test_auth_logout.py, test_auth_refresh.py, test_clients.py, test_users.py, test_demandes.py, etc. — 394 tests backend au total).
A17: 3.3 | B17: Phase 3 | C17: Tests | D17: 🟢 Normale | E17: Tests Users & Demandes | F17: Users: CRUD + restriction rôle. Demandes: 4 types, changement statut, assignation, clôture. | G17: Complété | H17: 1j | I17: tests/test_users.py · test_demandes.py | M17: [Audit 14/08] fichiers de tests existent et sont complets (test_auth_login.py, test_auth_logout.py, test_auth_refresh.py, test_clients.py, test_users.py, test_demandes.py, etc. — 394 tests backend au total).
A18: 3.4 | B18: Phase 3 | C18: Tests | D18: 🟢 Normale | E18: Tests Interactions & Fichiers | F18: Interactions: création + changement statut auto. Fichiers: upload/download, MIME, isolation tenant. | G18: Complété | H18: 1j | I18: tests/test_interactions.py · test_fichiers.py (nouveaux) | J18: 2.3 | M18: [Audit 14/08] fichiers de tests existent et sont complets (test_auth_login.py, test_auth_logout.py, test_auth_refresh.py, test_clients.py, test_users.py, test_demandes.py, etc. — 394 tests backend au total).
A19: 4.1 | B19: Phase 4 | C19: Frontend | D19: 🔵 Normale | E19: Services API génériques (clients, sites, contacts, demandes, users) | F19: Un fichier service par ressource sur le modèle authService.js. Pas de fetch direct dans les composants. | G19: Complété | H19: ½j | I19: frontend/src/services/*.js (nouveaux) | J19: 1.1 | M19: [Audit 14/08] frontend intégralement livré, architecturé différemment du plan initial (pas de vue DemandesView.vue unique : IssuesView/OrdersView/ShiftsView par type de demande + Workspace pour la création ; navigation réelle = Menu2.vue, pas Navigation.vue, orpheline).
A20: 4.2 | B20: Phase 4 | C20: Frontend | D20: 🔵 Normale | E20: Vue Clients — liste, détail, formulaire | F20: v-data-table avec recherche/pagination. Formulaire dans dialog. Afficher sites rattachés. Routes /clients, /clients/:id. | G20: Complété | H20: 1.5j | I20: views/ClientsView.vue · ClientDetailView.vue · router/index.js | J20: 4.1 | M20: [Audit 14/08] frontend intégralement livré, architecturé différemment du plan initial (pas de vue DemandesView.vue unique : IssuesView/OrdersView/ShiftsView par type de demande + Workspace pour la création ; navigation réelle = Menu2.vue, pas Navigation.vue, orpheline).
A21: 4.3 | B21: Phase 4 | C21: Frontend | D21: 🔵 Normale | E21: Vue Sites & Contacts | F21: Sites: liste filtrée par client. Contacts: recherche par nom/fonction, liens clients/sites. | G21: Complété | H21: 1.5j | I21: views/SitesView.vue · ContactsView.vue · router/index.js | J21: 4.1 | M21: [Audit 14/08] frontend intégralement livré, architecturé différemment du plan initial (pas de vue DemandesView.vue unique : IssuesView/OrdersView/ShiftsView par type de demande + Workspace pour la création ; navigation réelle = Menu2.vue, pas Navigation.vue, orpheline).
A22: 4.4 | B22: Phase 4 | C22: Frontend | D22: 🔵 Normale | E22: Vue Demandes — liste, création par type, détail + timeline | F22: Filtres (statut/priorité/type/client). 4 sous-formulaires. Timeline interactions + PJ. Routes /demandes, /demandes/new, /demandes/:id. | G22: Complété | H22: 3j | I22: views/DemandesView.vue · DemandeDetailView.vue + composants | J22: 4.1 | M22: [Audit 14/08] frontend intégralement livré, architecturé différemment du plan initial (pas de vue DemandesView.vue unique : IssuesView/OrdersView/ShiftsView par type de demande + Workspace pour la création ; navigation réelle = Menu2.vue, pas Navigation.vue, orpheline).
A23: 4.5 | B23: Phase 4 | C23: Frontend | D23: 🔵 Normale | E23: Brancher le Dashboard sur l'API réelle | F23: Remplacer useMockDashboardData.js par composable avec vrais appels. Ajouter /api/dashboard/stats backend. | G23: Complété | H23: 2j | I23: composables/useDashboardData.js · routes: /api/dashboard/stats (nouveau) | J23: 4.1 | M23: [Audit 14/08] frontend intégralement livré, architecturé différemment du plan initial (pas de vue DemandesView.vue unique : IssuesView/OrdersView/ShiftsView par type de demande + Workspace pour la création ; navigation réelle = Menu2.vue, pas Navigation.vue, orpheline).
A24: 4.6 | B24: Phase 4 | C24: Frontend | D24: 🔵 Normale | E24: Navigation globale et layout authentifié | F24: Menu latéral avec tous les liens. Afficher rôle et tenant actif. Bouton déconnexion. Menus conditionnels par rôle. | G24: Complété | H24: 1j | I24: components/Navigation.vue · Header.vue | J24: 1.4 | M24: [Audit 14/08] frontend intégralement livré, architecturé différemment du plan initial (pas de vue DemandesView.vue unique : IssuesView/OrdersView/ShiftsView par type de demande + Workspace pour la création ; navigation réelle = Menu2.vue, pas Navigation.vue, orpheline).
A25: 5.1 | B25: Phase 5 | C25: Qualité | D25: ⚪ Basse | E25: Supprimer les fichiers orphelins à la racine | F25: api.js, axios.js, main.css à la racine. Vérifier qu'ils ne sont importés nulle part puis supprimer après validation. | G25: À faire | H25: 30m | I25: api.js · axios.js · main.css (racine projet) | M25: [Audit 14/08] confirmé toujours présent (api.js/axios.js/main.css à la racine, non importés par frontend/src) — non fait.
A26: 5.2 | B26: Phase 5 | C26: Qualité | D26: ⚪ Basse | E26: Vérifier SQLALCHEMY_ECHO désactivé en production | F26: Confirmer ProductionConfig. Ajouter WARNING si DEBUG=False et ECHO=True. | G26: Complété | H26: 30m | I26: app/config.py | M26: [Audit 14/08] ProductionConfig.SQLALCHEMY_ECHO=False confirmé (app/config.py). Le WARNING runtime mentionné dans la description n'a pas été ajouté (mineur, non bloquant).
A27: 5.3 | B27: Phase 5 | C27: Documentation | D27: ⚪ Basse | E27: Mettre à jour README.md et PROJECT_STRUCTURE.md | F27: Nouveaux endpoints, flow multi-tenant, état réel. Ajouter changelog horodaté. Déplacer docs/ si nécessaire. | G27: Complété | H27: 1j | I27: README.md · PROJECT_STRUCTURE.md | M27: [Audit 14/08] tenus à jour en continu via changelogs versionnés depuis (dernière entrée : v1.10.0, 14/08).
A28: 5.4 | B28: Phase 5 | C28: Tests | D28: ⚪ Basse | E28: Audit final et couverture de tests (objectif 80%+) | F28: pytest --cov=app --cov-report=html. Identifier zones non couvertes. Tester migrations sous Docker PostgreSQL. | G28: En cours | H28: ½j | I28: backend/tests/ · docker-compose.yml | J28: 3.4 | M28: Baseline formelle mesuree le 14/08 : pytest --cov=app -> 64% global (7735 stmts, 2786 miss), 398 tests. Points forts (>=95%) : models/ quasi tous, routes/telephony.py 87%, routes/auth.py 85%. Points faibles notables : services/reencrypt.py 0%, routes/settings.py 19%, routes/prestataires.py 20%, scripts/seed_prestataires.py 11%, utils/crypto.py 54%, utils/login_throttle.py 59%, services/sla.py 51%, routes/demandes.py 62%. Objectif 80%+ delibrement reporte a un chantier dedie futur (scope trop large pour cette passe) — decision actee avec l'utilisateur le 14/08.
A29: 6.1 | B29: Phase 6 | C29: Backend | D29: 🟡 Haute | E29: Flag tenant integrations.erp (channel_erp) | F29: Colonne Tenant.channel_erp (motif channel_telephonie/email/chat), pas une dérivation pure dans tenant_features() — écart assumé par rapport à la note initiale ("channel_odoo écarté") : le motif column-on-Tenant déjà utilisé pour téléphonie/email/chat a été jugé plus cohérent qu'une exception. Exposé via tenant_features() (ch["erp"], config_state.erp_configured, integrations.erp). | G29: Complété | H29: ½j | I29: app/models/tenant.py · app/services/tenant_features.py · app/routes/tenants.py · migrations/versions/c1b16fed65e1_erp_foundations.py | K29: 2026-08-14 | L29: 2026-08-14 | M29: [14/08] Erp, pas Odoo (préfixe générique du plan, décision actée). Éditable via PUT /api/tenants/<id> (ADMIN global), même contrat que les channel_* existants.
A30: 6.2 | B30: Phase 6 | C30: Backend | D30: 🟡 Haute | E30: Modèle + migration ErpConfig | F30: 1 ligne par tenant : company_id ERP (instance partagée, pas de base/URL par tenant — §2.3) + 3 champs EncryptedText (url_erp/admin_username/admin_password) pour l'accès direct admin (§4.4, voir 6.9). TypeDecorator EncryptedText déjà présent (crypto.py, Email.subject/body_text) mais jusqu'ici jamais réutilisé ailleurs — désormais un 2e usage. | G30: Complété | H30: 1j | I30: app/models/erp.py (nouveau) · migrations/versions/c1b16fed65e1_erp_foundations.py | J30: 6.1 | K30: 2026-08-14 | L30: 2026-08-14 | M30: [14/08] Nom de fichier/table erp_config (pas odoo.py/odoo_config) — cf. décision de préfixe 6.1.
A31: 6.3 | B31: Phase 6 | C31: Backend | D31: 🟡 Haute | E31: Modèle + migration erp_sync_queue | F31: File de retry : tenant_id, flux, payload (JSON), status (pending|in_flight|done|failed, String), attempts, error, locked_at/locked_until (verrouillage anti-double-traitement §2.4, absent du precedent le plus proche email_outbox). | G31: Complété | H31: ½j | I31: app/models/erp.py · migrations/versions/c1b16fed65e1_erp_foundations.py | J31: 6.2 | K31: 2026-08-14 | L31: 2026-08-14 | M31: [14/08] Colonne next_retry_at de la description initiale remplacée par locked_at/locked_until (verrouillage court, motif différent d'un simple 'prochaine tentative à').
A32: 6.4 | B32: Phase 6 | C32: Backend | D32: 🟡 Haute | E32: Route /api/settings/erp (GET/PUT/test) + /api/settings/general (§4.3) | F32: Calque de routes/settings.py (SMTP) : GET ouvert à tout membre, PUT/test réservés @tenant_admin_required, test retourne toujours 200 (ok:true/false). Ajout non prévu à l'origine : /api/settings/general (GET/PUT) pour document_blocking_expired/vacation_delay_threshold_minutes (§4.3, réglages tenant sans rapport direct à ERP mais posés dès cette phase, prérequis Phases 9/10). | G32: Complété | H32: 1j | I32: app/routes/settings.py | J32: 6.2 | K32: 2026-08-14 | L32: 2026-08-14 | M32: [14/08] Les champs url_erp/admin_username/admin_password (accès direct §4.4) sont explicitement REFUSÉS par PUT /settings/erp (tenant-admin) — réservés à l'ADMIN global via /api/erp/direct-access (6.9).
A33: 6.5 | B33: Phase 6 | C33: Backend | D33: 🟢 Normale | E33: Service erp_client.py (wrapper xmlrpc.client) | F33: ErpClient.execute_kw(company_id, model, method, args, kwargs) — company_id obligatoire (jamais de défaut implicite), with_context(allowed_company_ids=…) injecté systématiquement (§2.3). Injecté par paramètre (jamais singleton) pour permettre FakeErpClient en test (§2.5, voir 6.7). Transport XML-RPC avec timeout socket configurable (défaut 3s, §2.1). | G33: Complété | H33: 1j | I33: app/services/erp_client.py (nouveau) | J33: 6.2 | K33: 2026-08-14 | L33: 2026-08-14
A34: 6.6 | B34: Phase 6 | C34: Backend | D34: 🟢 Normale | E34: Commande flask erp-sync-dispatch + cron | F34: Traite erp_sync_queue (pending/failed sous le seuil de tentatives, non verrouillées), même patron que notifications-dispatch (dispatch_emails). Cron+queue, pas Celery (§2.1), conforme à la décision actée. | G34: En cours | H34: ½j | I34: app/services/erp_sync.py (nouveau) · app/__init__.py | J34: 6.3, 6.5 | K34: 2026-08-14 | M34: [14/08] Verrouillage/déverrouillage et transitions de statut opérationnels et testés — MAIS aucun flux réel n'est encore rejoué (chaque ligne traitée échoue avec un message explicite 'non implémenté'), car aucun flux n'écrit encore dans la queue avant la Phase 7 (erp_partners). À rouvrir en Phase 7 pour brancher la vraie logique de rejeu (search-then-write par x_permatel_ref, §2.4).
A35: 7.1 | B35: Phase 7 | C35: Infra | D35: 🟡 Haute | E35: Conteneur Odoo 18 Community + Postgres dédié | F35: Sur réseau interne (permatel_internal), jamais exposé sur l'hôte. | G35: À faire | H35: 1j | I35: docker-compose.yml | J35: 6.6
A36: 7.2 | B36: Phase 7 | C36: Infra | D36: 🟡 Haute | E36: Multi-database Odoo (dbfilter, list_db=False) | F36: 1 base Odoo par tenant PERMATEL, rôle Postgres distinct par base. | G36: À faire | H36: 1j | I36: infra Odoo (config serveur) | J36: 7.1
A37: 7.3 | B37: Phase 7 | C37: Backend | D37: 🟢 Normale | E37: Modèle + migration odoo_partners | F37: Copie locale des partenaires synchronisés (odoo_id, sync_status, last_synced_at). | G37: À faire | H37: ½j | I37: app/models/odoo.py · migrations/versions/ | J37: 6.2
A38: 7.4 | B38: Phase 7 | C38: Backend | D38: 🟢 Normale | E38: Commande flask odoo-sync-partners (bidirectionnel) | F38: Cron 15 min par défaut, configurable par tenant (F1 du CDC). | G38: À faire | H38: 1.5j | I38: app/scripts/odoo_sync.py | J38: 7.2, 7.3, 6.5
A39: 7.5 | B39: Phase 7 | C39: Frontend | D39: 🟢 Normale | E39: Indicateur de fraîcheur last_synced_at | F39: Affiché sur les vues Clients/Prestataires quand l'intégration Odoo est active pour le tenant. | G39: À faire | H39: ½j | I39: frontend/src/views/ClientsView.vue · PartnerView.vue | J39: 7.4
A40: 8.1 | B40: Phase 8 | C40: Backend | D40: 🟢 Normale | E40: Hook demande commande → devis Odoo (F2) | F40: Tentative synchrone (timeout court 2-3s) juste après le commit, échec → odoo_sync_queue. | G40: À faire | H40: 1j | I40: app/routes/demandes.py | J40: 6.3, 6.5, 7.4
A41: 8.2 | B41: Phase 8 | C41: Backend | D41: 🟢 Normale | E41: Modèles + migration odoo_devis / odoo_factures | F41: Copie locale en lecture (F4 : retour Odoo → PERMATEL). | G41: À faire | H41: ½j | I41: app/models/odoo.py · migrations/versions/ | J41: 6.2
...

Sheet Changelog
A1: CHANGELOG — HISTORIQUE DES MISES À JOUR
A2: Date | B2: Tâche ID | C2: Titre | D2: Ancien statut | E2: Nouveau statut | F2: Commentaire
A3: 2026-05-10 | B3: — | C3: Création du fichier de suivi | D3: — | E3: Initialisé | F3: Audit initial du 2026-05-10
A4: 2026-05-10 | B4: 1.1 | C4: Réactiver @tenant_required() sur clients/sites/contacts | D4: À faire | E4: Complété | F4: Fix imports backend.app.utils → app.utils. Corrigé delete_contact (jwt→tenant_required). Corrigé demandes.py.
A5: 2026-05-10 | B5: 1.2 | C5: Appliquer @role_required() aux endpoints d'administration | D5: À faire | E5: Complété | F5: ADMIN requis sur update_user, update_user_status, add/update/remove tenant users. Fix import users.py.
A6: 2026-05-10 | B6: 1.3 | C6: Corriger docker-compose.yml (pas de secrets hardcodés) | D6: À faire | E6: Complété | F6: Toutes les valeurs via ${VAR}. Healthcheck DB. .env racine créé. .env.example documenté.
A7: 2026-05-10 | B7: 1.4 | C7: Guard router branché sur Pinia | D7: À faire | E7: Complété | F7: useAuthStore.isAuthenticated. meta.guestOnly sur /login. returnUrl mémorisé. Bypass dev supprimé.
A8: 2026-05-10 | B8: 1.5 | C8: Intercepteur refresh automatique | D8: À faire | E8: Complété | F8: File d'attente failedQueue, flag isRefreshing, retry _retry. logoutSilent + redirect si refresh échoue.
A9: 2026-08-14 | B9: 2.1 | C9: Réactiver et compléter le blueprint Prestataires | D9: À faire | E9: Complété | F9: Audit 14/08 : déjà implémenté (voir Notes ligne)
A10: 2026-08-14 | B10: 2.2 | C10: Créer les routes Agents de sécurité | D10: À faire | E10: Complété | F10: Audit 14/08 : déjà implémenté (voir Notes ligne)
A11: 2026-08-14 | B11: 2.3 | C11: Créer les routes Interactions | D11: À faire | E11: Complété | F11: Audit 14/08 : déjà implémenté (voir Notes ligne)
A12: 2026-08-14 | B12: 2.4 | C12: Créer les routes Fichiers (upload/download) | D12: À faire | E12: À faire | F12: Audit 14/08 : confirmé toujours non fait (aucune route/modèle Fichier câblé)
A13: 2026-08-14 | B13: 2.5 | C13: Implémenter le flow select-tenant côté frontend | D13: À faire | E13: Complété | F13: Audit 14/08 : déjà implémenté (voir Notes ligne)
... A57: 2026-07-27 | B57: 11.1-11.7 | C57: Phase 11 (fondations backend Téléphonie) implémentée | D57: À faire | E57: Complété | F57: Migrations + modèles pbx_connectors/pbx_domains_tenants + extension telephony_events, routes/telephony.py (ingestion, KPIs, active-calls, CRUD connecteurs, settings tenant), tenant_features() mis à jour. 16 tests ajoutés, 188/188 verts.
A58: 2026-07-27 | B58: 11bis.1-11bis.3 | C58: Phase 11bis (infra WebSocket) implémentée + validée en test de charge Docker réel | D58: À faire | E58: Complété
A59: 2026-07-27 | B59: 12.1-12.4, 12.6-12.8 | C59: Phase 12 (connecteur FusionPBX/ESL) implémentée : Core Connector, ESLAdapter, bootstrap config, UI admin + réglages tenant | D59: À faire | E59: Complété
A60: 2026-07-27 | B60: 12.5 | C60: Résilience connecteur : reconnexion/backoff faits, file Redis restante | D60: À faire | E60: En cours
A61: 2026-07-27 | B61: 12.7-12.9 | C61: Pivot Phase 12 : connecteur PBX tenant-scope (comme SMTP/IMAP) + Sync temps reel Redis + heartbeat statut | D61: A faire | E61: Complete
A62: 2026-07-28 | B62: 12.10-12.11 | C62: Deux bugs de production corriges (deadlock connecteur, routage WebSocket Nginx) suite au raccordement a un FusionPBX reel | D62: A faire | E62: Complété
A63: 2026-07-29 | B63: 13.1-14.4 | C63: Phase 13/14 : config relocalisée sous Intégrations, Supervision temps réel (grille agents CC-Agent-Status), webhook CDR FusionPBX (mod_json_cdr, jeton par connecteur), Rapports > Téléphonie (historique/export CSV/enregistrements/export ZIP). Six correctifs de parsing CDR validés contre trafic réel. | D63: À faire | E63: Complété | F63: 236 tests backend au total
A64: 2026-08-14 | B64: 4.7 | C64: Fix footer masquant les tiroirs d'édition | D64: — | E64: Complété | F64: bottom:0 -> var(--v-layout-bottom, 34px) sur .ecd-overlay/.ead-overlay.
A65: 2026-08-14 | B65: 5.5 | C65: Fix VITE_INACTIVITY_TIMEOUT_MINUTES non propagé au build Docker | D65: — | E65: Complété | F65: Build arg frontend dérivé de SESSION_INACTIVITY_TIMEOUT_MINUTES (backend), plus de variable VITE_ séparée à synchroniser à la main.
A66: 2026-08-14 | B66: 13.3 | C66: Fix affichage agent déduit (appels sortants directs) | D66: — | E66: Complété | F66: Gate frontend corrigé (agent_name/agent_login au lieu de agent_login seul) + indice visuel « déduit ».
A67: 2026-08-14 | B67: 16.4 | C67: Colonnes Dernière modification/Clôturé le (Commandes/Anomalies) | D67: — | E67: Complété | F67: closed_by_nom ajouté à la sérialisation ; closed_by_id posé par on_status_change().
A68: 2026-08-14 | B68: 17.1 | C68: Nouvelle vue Mon Profil (self-service) | D68: — | E68: Complété | F68: PATCH /api/users/me (jwt_required, sans role ADMIN) pour nom/prénom/avatar ; mot de passe via l'endpoint self-service existant.
A69: 2026-08-14 | B69: 5.4 | C69: Baseline formelle de couverture de tests (pytest --cov) | D69: À faire | E69: En cours | F69: 64% global mesure et documente par module ; objectif 80%+ reporte a un chantier dedie futur (decision utilisateur).
A70: 2026-08-14 | B70: 6.1-6.6 | C70: Phase 6 ERP — fondations transverses (flag, ErpConfig, erp_sync_queue, routes settings, erp_client.py, dispatch) | D70: À faire | E70: Complété/En cours | F70: Renommage Odoo->Erp (motif générique du plan). erp-sync-dispatch reste En cours : verrouillage opérationnel, rejeu réel différé Phase 7.
A71: 2026-08-14 | B71: 6.7-6.10 | C71: Ajouts au périmètre Phase 6 (§5 du plan, hors 6 lignes initiales du suivi) | D71: — | E71: Complété/En cours | F71: fake_erp_client.py, flask erp-backfill (squelette), réglages tenant §4.3, accès direct ERP audité §4.4.
